Workbook

Sheet Encoder
C2: Encoder
C3: Segmento de captación: Son los cables que salen directo de cada encoder.
C4: Segmento de transmisión: Son los cables que se conectan a la terminal del cable enroscado. Es el intermedio entre captación y transmisión.
C5: SDP: Donde se encuentra agrupadas las señales de encoders, frenos y finales de carrera
C6: Cadera: No tiene conexión ni en el segmento de transmisión ni SDP.
H9: Segmento de captación | M9: Segmento de transmisión | R9: SDP
C10: ID | D10: Lugar | E10: Motor | F10: Marca | G10: Pasos | H10: V_c | I10: G_c | J10: A_c | K10: B_c | L10: Z_c | M10: V_t | N10: G_t | O10: A_t | P10: B_t | Q10: Z_t | R10: V_s | S10: V_s_PIN | T10: G_s | U10: G_s_PIN | V10: A_s | W10: A_s_PIN | X10: B_s | Y10: B_s_PIN | Z10: Z_s | AA10: Z_s_PIN
C11: ENC5 | D11: MUÑECA | E11: NA | F11: ? | G11: ? | H11: ROJO | I11: GRIS | J11: Azul | K11: VERDE | L11: Amarillo | M11: ROJO | N11: AZUL | O11: VERDE CLARO | P11: AMARILLO | Q11: GRIS | R11: =SDP!E58 -> BLANCO | S11: =SDP!D58 -> 15 | T11: =SDP!E56 -> AZUL | U11: =SDP!D56 -> 13 | V11: =SDP!E33 -> MORADO | W11: =SDP!D33 -> 7 | X11: =SDP!E51 -> BLANCO | Y11: =SDP!D51 -> 8 | Z11: =SDP!E50 -> BLANCO | AA11: =SDP!D50 -> 7
C12: ENC4 | D12: ANTEBRAZO | E12: NA | F12: SHARP1GR112 | G12: 96 | H12: ROJO | I12: GRIS | J12: Azul | K12: VERDE | L12: Amarillo | M12: ROJO | N12: AZUL | O12: VERDE CLARO | P12: AMARILLO | Q12: GRIS | R12: =SDP!E41 -> ROJO | S12: =SDP!D41 -> 15 | T12: =SDP!E39 -> BLANCO | U12: =SDP!D39 -> 13 | V12: =SDP!E52 -> BLANCO | W12: =SDP!D52 -> 9 | X12: =SDP!E35 -> AMARILLO | Y12: =SDP!D35 -> 9 | Z12: =SDP!E34 -> VERDE | AA12: =SDP!D34 -> 8
C13: ENC3 | D13: CODO | E13: 5023042 | F13: 200 | G13: 200 | H13: AMARILLO | I13: VERDE | J13: ROJO | K13: GRIS | L13: AZUL | M13: NA | N13: NA | O13: NA | P13: NA | Q13: NA | R13: =SDP!E59 -> GRIS | S13: =SDP!D59 -> 16 | T13: =SDP!E57 -> AZUL | U13: =SDP!D57 -> 14 | V13: =SDP!E36 -> MORADO | W13: =SDP!D36 -> 10 | X13: =SDP!E54 -> GRIS | Y13: =SDP!D54 -> 11 | Z13: =SDP!E53 -> GRIS | AA13: =SDP!D53 -> 10
C14: ENC2 | D14: HOMBRO | E14: 5023046 | F14: 200 | G14: 200 | H14: AMARILLO | I14: VERDE | J14: ROJO | K14: GRIS | L14: AZUL | M14: NA | N14: NA | O14: NA | P14: NA | Q14: NA | R14: =SDP!E42 -> ROJO | S14: =SDP!D42 -> 16 | T14: =SDP!E40 -> GRIS | U14: =SDP!D40 -> 14 | V14: =SDP!E55 -> GRIS | W14: =SDP!D55 -> 12 | X14: =SDP!E38 -> AMARILLO | Y14: =SDP!D38 -> 12 | Z14: =SDP!E37 -> VERDE | AA14: =SDP!D37 -> 11
C15: ENC1 | D15: CADERA | E15: 5023008 | F15: SHARP GP1R112 | H15: AMARILLO | I15: VERDE | J15: ROJO | K15: GRIS | L15: AZUL | M15: NA | N15: NA | O15: NA | P15: NA | Q15: NA | R15: NA | S15: NA | T15: NA | U15: NA | V15: NA | W15: NA | X15: NA | Y15: NA | Z15: NA | AA15: NA
AH17: Antebrazo | AI17: 5023046
AG18: Rojo | AH18: v | AI18: amarillo | AJ18: v
AG19: Gris | AH19: g | AI19: verde | AJ19: g
AG20: Verde | AH20: b | AI20: gris | AJ20: b
AG21: Azul | AH21: a | AI21: rojo | AJ21: a
AG22: Amarillo | AH22: z | AI22: azul | AJ22: z
AG23: Negro | AI23: negro

Sheet LS
B3: Finales de carrera [LS]
B4: SDP: Se refiere a la terminal que sale del "segmentos de distribución principal".
B5: Los finales de carrera se encuentran en el segmento B.
B6: LS1: No está conectado al SDP, tiene su terminal independiente (suelta)
D10: CAPTACIÓN | E10: TRANSMISIÓN | F10: SDP
B11: ID | C11: Lugar | D11: COLOR C | E11: COLOR T | F11: Cara | G11: Pin | H11: COLOR S
B12: LS5 | C12: MUÑECA | D12: BLANCO | E12: BLANCO | F12: INFERIOR | G12: 2 | H12: AZUL
B13: LS5 | C13: MUÑECA | D13: NEGRO | E13: NEGRO | F13: INFERIOR | G13: 4 | H13: NEGRO
B14: LS4 | C14: ANTEBRAZO | D14: BLANCO | E14: BLANCO | F14: SUPERIOR | G14: 2 | H14: VERDE
B15: LS4 | C15: ANTEBRAZO | D15: NEGRO | E15: NEGRO | F15: SUPERIOR | G15: 4 | H15: NEGRO
B16: LS3 | C16: CODO | D16: BLANCO | E16: BLANCO | F16: INFERIOR | G16: 3 | H16: AMARILLO
B17: LS3 | C17: CODO | D17: NEGRO | E17: NEGRO | F17: INFERIOR | G17: 5 | H17: NEGRO
B18: LS2 | C18: HOMBRO | D18: BLANCO | E18: BLANCO | F18: SUPERIOR | G18: 3 | H18: ROJO
B19: LS2 | C19: HOMBRO | D19: NEGRO | E19: NEGRO | F19: SUPERIOR | G19: 5 | H19: NEGRO
B20: LS1 | C20: CADERA | D20: BLANCO | E20: BLANCO | F20: NA | G20: NA | H20: NA
B21: LS1 | C21: CADERA | D21: NEGRO | E21: NEGRO | F21: NA | G21: NA | H21: NA

Sheet SDP
B2: Segmentos de distribución principal
B3: Son los dos cables enroscados que agrupa las señales de encoders, sensores de final de carrera y frenos.
B4: Segmento A: De ellos salen las señales de control de los motores y frenos
B5: Segmento B: Terminal donde se agrupan los encoders, finales de carrera y frenos
B6: Cara superior: Donde se encuentra la muesca de la terminal
B8: Segmento A
D9: CAPTACIÓN | F9: TRANSMISIÓN | H9: SDP
B10: ID | C10: LUGAR | D10: C1 | E10: C2 | F10: T1 | G10: T2 | H10: S1 | I10: S2
B11: M1 | C11: CADERA | D11: NA | E11: NA | F11: NA | G11: NA | H11: ROJO | I11: NEGRO
B12: M2 | C12: HOMBRO | D12: NEGRO | E12: ROJO | F12: NA | G12: NA | H12: ROJO | I12: CAFÉ
B13: M3 | C13: ANTEBRAZO | D13: NEGRO | E13: ROJO | F13: NA | G13: NA | H13: NARANJA | I13: AMARILLO
B14: M4 | C14: CODO | D14: NEGRO | E14: BLANCO | F14: NEGRO | G14: BLANCO | H14: AZUL | I14: VERDE
B15: M5 | C15: MUÑECA | D15: NEGRO | E15: BLANCO | F15: NEGRO | G15: BLANCO | H15: GRIS | I15: MORADO
D18: CAPTACIÓN | F18: TRANSMISIÓN | H18: SDP
B19: ID | C19: LUGAR | D19: C1 | E19: C2 | F19: T1 | G19: T2 | H19: S1 | I19: S2
B20: B2 | C20: HOMBRO | D20: BLANCO | E20: BLANCO | F20: BLANCO | G20: NEGRO | H20: ROSA | I20: AZUL
B21: B3 | C21: CODO | D21: BLANCO | E21: BLANCO | F21: BLANCO | G21: NEGRO | H21: BLANCO | I21: NEGRO
B24: Segmento B
C25: SDP
B26: ID Señal | C26: Cara | D26: Pin | E26: Color2
B27: VACÍO | C27: SUPERIOR | D27: 1 | E27: VACÍO
B28: LS4 | C28: SUPERIOR | D28: 2 | E28: VERDE
B29: LS2 | C29: SUPERIOR | D29: 3 | E29: ROJO
B30: LS4 | C30: SUPERIOR | D30: 4 | E30: NEGRO
B31: LS2 | C31: SUPERIOR | D31: 5 | E31: NEGRO
B32: VACÍO | C32: SUPERIOR | D32: 6 | E32: VACÍO
B33: A5 | C33: SUPERIOR | D33: 7 | E33: MORADO
B34: Z4 | C34: SUPERIOR | D34: 8 | E34: VERDE
B35: B4 | C35: SUPERIOR | D35: 9 | E35: AMARILLO
B36: A3 | C36: SUPERIOR | D36: 10 | E36: MORADO | K36: Alzado
B37: Z2 | C37: SUPERIOR | D37: 11 | E37: VERDE | K37: =B27 -> VACÍO | L37: =B44 -> VACÍO
B38: B2 | C38: SUPERIOR | D38: 12 | E38: AMARILLO | K38: =B28 -> LS4 | L38: =B45 -> LS5
B39: G4 | C39: SUPERIOR | D39: 13 | E39: BLANCO | K39: =B29 -> LS2 | L39: =B46 -> LS3
B40: G2 | C40: SUPERIOR | D40: 14 | E40: GRIS | K40: =B30 -> LS4 | L40: =B47 -> LS5
B41: V4 | C41: SUPERIOR | D41: 15 | E41: ROJO | K41: =B31 -> LS2 | L41: =B48 -> LS3
B42: V2 | C42: SUPERIOR | D42: 16 | E42: ROJO | K42: =B32 -> VACÍO | L42: =B49 -> VACÍO
B43: Extra? | C43: SUPERIOR | D43: 17 | E43: NEGRO | K43: =B33 -> A5 | L43: =B50 -> Z5
B44: VACÍO | C44: INFERIOR | D44: 1 | E44: VACÍO | K44: =B34 -> Z4 | L44: =B51 -> B5
B45: LS5 | C45: INFERIOR | D45: 2 | E45: AZUL | K45: =B35 -> B4 | L45: =B52 -> A4
B46: LS3 | C46: INFERIOR | D46: 3 | E46: AMARILLO | J46: Muesca | K46: =B36 -> A3 | L46: =B53 -> Z3
...
